2025-01-28 13:49:26,283 ERROR scheduler Exception in Enqueue Events for Site dcode.com
Traceback (most recent call last):
  File "/home/aeroplane/frappe-bench/env/lib/python3.11/site-packages/pymysql/connections.py", line 649, in connect
    sock = socket.create_connection(
           ^^^^^^^^^^^^^^^^^^^^^^^^^
  File "/usr/lib/python3.11/socket.py", line 863, in create_connection
    raise exceptions[0]
  File "/usr/lib/python3.11/socket.py", line 848, in create_connection
    sock.connect(sa)
ConnectionRefusedError: [Errno 111] Connection refused

During handling of the above exception, another exception occurred:

Traceback (most recent call last):
  File "/home/aeroplane/frappe-bench/apps/frappe/frappe/utils/scheduler.py", line 75, in enqueue_events_for_site
    if is_scheduler_inactive():
       ^^^^^^^^^^^^^^^^^^^^^^^
  File "/home/aeroplane/frappe-bench/apps/frappe/frappe/utils/scheduler.py", line 117, in is_scheduler_inactive
    if is_scheduler_disabled(verbose=verbose):
       ^^^^^^^^^^^^^^^^^^^^^^^^^^^^^^^^^^^^^^
  File "/home/aeroplane/frappe-bench/apps/frappe/frappe/utils/scheduler.py", line 130, in is_scheduler_disabled
    frappe.db.get_single_value("System Settings", "enable_scheduler")
  File "/home/aeroplane/frappe-bench/apps/frappe/frappe/database/database.py", line 837, in get_single_value
    ).run()
      ^^^^^
  File "/home/aeroplane/frappe-bench/apps/frappe/frappe/query_builder/utils.py", line 87, in execute_query
    result = frappe.db.sql(query, params, *args, **kwargs)  # nosemgrep
             ^^^^^^^^^^^^^^^^^^^^^^^^^^^^^^^^^^^^^^^^^^^^^
  File "/home/aeroplane/frappe-bench/apps/frappe/frappe/database/database.py", line 207, in sql
    self.connect()
  File "/home/aeroplane/frappe-bench/apps/frappe/frappe/database/database.py", line 112, in connect
    self._conn: "MariadbConnection" | "PostgresConnection" = self.get_connection()
                                                             ^^^^^^^^^^^^^^^^^^^^^
  File "/home/aeroplane/frappe-bench/apps/frappe/frappe/database/mariadb/database.py", line 107, in get_connection
    conn = self._get_connection()
           ^^^^^^^^^^^^^^^^^^^^^^
  File "/home/aeroplane/frappe-bench/apps/frappe/frappe/database/mariadb/database.py", line 113, in _get_connection
    return self.create_connection()
           ^^^^^^^^^^^^^^^^^^^^^^^^
  File "/home/aeroplane/frappe-bench/apps/frappe/frappe/database/mariadb/database.py", line 116, in create_connection
    return pymysql.connect(**self.get_connection_settings())
           ^^^^^^^^^^^^^^^^^^^^^^^^^^^^^^^^^^^^^^^^^^^^^^^^^
  File "/home/aeroplane/frappe-bench/env/lib/python3.11/site-packages/pymysql/connections.py", line 361, in __init__
    self.connect()
  File "/home/aeroplane/frappe-bench/env/lib/python3.11/site-packages/pymysql/connections.py", line 716, in connect
    raise exc
pymysql.err.OperationalError: (2003, "Can't connect to MySQL server on '127.0.0.1' ([Errno 111] Connection refused)")
